<!-- <?xml version="1.0"> -->

<!-- <?xml version="1.0" encoding="utf-8"?> -->
<!-- This URDF was automatically created by SolidWorks to URDF Exporter! Originally created by Stephen Brawner (brawner@gmail.com) 
     Commit Version: 1.6.0-4-g7f85cfe  Build Version: 1.6.7995.38578
     For more information, please see http://wiki.ros.org/sw_urdf_exporter -->
<robot
  name="urdf_and_meshes_of_the_robot" >
   <link name="base_link"/>  <!-- Dummy link added -->

  <joint name="base_joint" type="fixed">
    <parent link="base_link"/>
    <child link="BODY_link"/>
  </joint>
  
  <link
    name="BODY_link">
    <inertial>
      <origin
        xyz="7.3062E-18 0.0022646 -0.021333"
        rpy="0 0 0" />
      <mass
        value="1.25696760938142" />
      <inertia
        ixx="0.0045914"
        ixy="1.4409E-18"
        ixz="-1.9104E-19"
        iyy="0.004286"
        iyz="0.00013476"
        izz="0.0063727" />
    </inertial>
    <visual>
      <origin
        xyz="0 0 0"
        rpy="0 0 0" />
      <geometry>
        <mesh
          filename="file:///home/mickyas/ros2_ws/src/urdf_and_meshes_of_the_robot/meshes/BODY_link.STL"/>
      </geometry>
      <material
        name="Alumuniam 1060 Alloy">
        <color
          rgba="0.89804 0.91765 0.92941 1" />
      </material>
    </visual>
    <collision>
      <origin
        xyz="0 0 0"
        rpy="0 0 0" />
      <geometry>
        <mesh
          filename="file:///home/mickyas/ros2_ws/src/urdf_and_meshes_of_the_robot/meshes/BODY_link.STL" />
      </geometry>
    </collision>
  </link>
  <link
    name="Upper_left_leg">
    <inertial>
      <origin
        xyz="6.6396E-09 -0.10715 0.021958"
        rpy="0 0 0" />
      <mass
        value="0.32627" />
      <inertia
        ixx="0.0021991"
        ixy="-1.3036E-10"
        ixz="-2.948E-10"
        iyy="4.2897E-05"
        iyz="3.6799E-06"
        izz="0.0022214" />
    </inertial>
    <visual>
      <origin
        xyz="0 0 0"
        rpy="0 0 0" />
      <geometry>
        <mesh
          filename="file:///home/mickyas/ros2_ws/src/urdf_and_meshes_of_the_robot/meshes/Upper_left_leg.STL" />
      </geometry>
      <material
        name="Alumuniam 1060 Alloy">
        <color
          rgba="0.29804 0.29804 0.29804 1" />
      </material>
    </visual>
    <collision>
      <origin
        xyz="0 0 0"
        rpy="0 0 0" />
      <geometry>
        <mesh
          filename="file:///home/mickyas/ros2_ws/src/urdf_and_meshes_of_the_robot/meshes/Upper_left_leg.STL" />
      </geometry>
    </collision>
  </link>
  <joint
    name="Upper_left_joint"
    type="revolute">
    <origin
      xyz="0.065 -0.0025 -0.055"
      rpy="1.5708 -0.5686 1.5708" />
    <parent
      link="BODY_link" />
    <child
      link="Upper_left_leg" />
    <axis
      xyz="0 0 -1" />
    <limit
      lower="-1.57"
      upper="1.57"
      effort="5"
      velocity="1" />
  </joint>
  <link
    name="Lower_left_leg">
    <inertial>
      <origin
        xyz="3.3987E-08 -0.095731 0.0075383"
        rpy="0 0 0" />
      <mass
        value="0.20779" />
      <inertia
        ixx="0.0010103"
        ixy="7.9033E-11"
        ixz="1.1732E-10"
        iyy="1.2421E-05"
        iyz="7.5525E-07"
        izz="0.0010151" />
    </inertial>
    <visual>
      <origin
        xyz="0 0 0"
        rpy="0 0 0" />
      <geometry>
        <mesh
          filename="file:///home/mickyas/ros2_ws/src/urdf_and_meshes_of_the_robot/meshes/Lower_left_leg.STL" />
      </geometry>
      <material
        name="Alumuniam 1060 Alloy">
        <color
          rgba="0.29804 0.29804 0.29804 1" />
      </material>
    </visual>
    <collision>
      <origin
        xyz="0 0 0"
        rpy="0 0 0" />
      <geometry>
        <mesh
          filename="file:///home/mickyas/ros2_ws/src/urdf_and_meshes_of_the_robot/meshes/Lower_left_leg.STL" />
      </geometry>
    </collision>
  </link>
  <joint
    name="Lower_left_joint"
    type="revolute">
    <origin
      xyz="0 -0.24941 0.032"
      rpy="0 0 -1.2888" />
    <parent
      link="Upper_left_leg" />
    <child
      link="Lower_left_leg" />
    <axis
      xyz="0 0 1" />
    <limit
      lower="-1.57"
      upper="1.57"
      effort="5"
      velocity="1" />
  </joint>
  <link
    name="Left_wheel">
    <inertial>
      <origin
        xyz="7.526E-08 -9.4982E-08 -0.021914"
        rpy="0 0 0" />
      <mass
        value="0.12382" />
      <inertia
        ixx="0.00019918"
        ixy="-2.4608E-10"
        ixz="-2.7634E-11"
        iyy="0.00019918"
        iyz="4.4186E-11"
        izz="0.0003757" />
    </inertial>
    <visual>
      <origin
        xyz="0 0 0"
        rpy="0 0 0" />
      <geometry>
        <mesh
          filename="file:///home/mickyas/ros2_ws/src/urdf_and_meshes_of_the_robot/meshes/Left_wheel.STL" />
      </geometry>
      <material
        name="Rubber">
        <color
          rgba="0.29804 0.29804 0.29804 1" />
      </material>
    </visual>
    <collision>
      <origin
        xyz="0 0 0"
        rpy="0 0 0" />
      <geometry>
        <mesh
          filename="file:///home/mickyas/ros2_ws/src/urdf_and_meshes_of_the_robot/meshes/Left_wheel.STL" />
      </geometry>
    </collision>
  </link>
  <joint
    name="left_joint"
    type="continuous">
    <origin
      xyz="0 -0.22885 0.015"
      rpy="3.1416 0 0.81783" />
    <parent
      link="Lower_left_leg" />
    <child
      link="Left_wheel" />
    <axis
      xyz="0 0 1" />
    <limit
      lower="-1.57"
      upper="1.57"
      effort="5"
      velocity="1" />
  </joint>
  <link
    name="Upper_right_link">
    <inertial>
      <origin
        xyz="9.6623E-09 -0.10715 0.021958"
        rpy="0 0 0" />
      <mass
        value="0.32627" />
      <inertia
        ixx="0.0021991"
        ixy="-1.7623E-10"
        ixz="-2.9281E-10"
        iyy="4.2897E-05"
        iyz="3.6798E-06"
        izz="0.0022214" />
    </inertial>
    <visual>
      <origin
        xyz="0 0 0"
        rpy="0 0 0" />
      <geometry>
        <mesh
          filename="file:///home/mickyas/ros2_ws/src/urdf_and_meshes_of_the_robot/meshes/Upper_right_link.STL" />
      </geometry>
      <material
        name="Alumuniam 1060 Alloy">
        <color
          rgba="0.29804 0.29804 0.29804 1" />
      </material>
    </visual>
    <collision>
      <origin
        xyz="0 0 0"
        rpy="0 0 0" />
      <geometry>
        <mesh
          filename="file:///home/mickyas/ros2_ws/src/urdf_and_meshes_of_the_robot/meshes/Upper_right_link.STL" />
      </geometry>
    </collision>
  </link>
  <joint
    name="Upper_right_joint"
    type="revolute">
    <origin
      xyz="-0.065 -0.0025 -0.055"
      rpy="1.5708 0.59611 -1.5708" />
    <parent
      link="BODY_link" />
    <child
      link="Upper_right_link" />
    <axis
      xyz="0 0 1" />
    <limit
      lower="-1.57"
      upper="1.57"
      effort="5"
      velocity="1" />
  </joint>
  <link
    name="Lower_right_link">
    <inertial>
      <origin
        xyz="3.29E-08 -0.095731 0.0075383"
        rpy="0 0 0" />
      <mass
        value="0.20779" />
      <inertia
        ixx="0.0010103"
        ixy="8.8706E-11"
        ixz="1.1747E-10"
        iyy="1.2421E-05"
        iyz="7.5523E-07"
        izz="0.0010151" />
    </inertial>
    <visual>
      <origin
        xyz="0 0 0"
        rpy="0 0 0" />
      <geometry>
        <mesh
          filename="file:///home/mickyas/ros2_ws/src/urdf_and_meshes_of_the_robot/meshes/Lower_right_link.STL" />
      </geometry>
      <material
        name="Alumuniam 1060 Alloy">
        <color
          rgba="0.29804 0.29804 0.29804 1" />
      </material>
    </visual>
    <collision>
      <origin
        xyz="0 0 0"
        rpy="0 0 0" />
      <geometry>
        <mesh
          filename="file:///home/mickyas/ros2_ws/src/urdf_and_meshes_of_the_robot/meshes/Lower_right_link.STL" />
      </geometry>
    </collision>
  </link>
  <joint
    name="Lower_right_joint"
    type="revolute">
    <origin
      xyz="0 -0.24941 0.034"
      rpy="0 0 1.3094" />
    <parent
      link="Upper_right_link" />
    <child
      link="Lower_right_link" />
    <axis
      xyz="0 0 1" />
    <limit
      lower="-1.57"
      upper="1.57"
      effort="5"
      velocity="1" />
  </joint>
  <link
    name="Right_wheel">
    <inertial>
      <origin
        xyz="2.9114E-08 -9.5306E-09 -0.021914"
        rpy="0 0 0" />
      <mass
        value="0.12382" />
      <inertia
        ixx="0.00019918"
        ixy="-2.1966E-10"
        ixz="-1.9165E-11"
        iyy="0.00019918"
        iyz="2.7688E-11"
        izz="0.0003757" />
    </inertial>
    <visual>
      <origin
        xyz="0 0 0"
        rpy="0 0 0" />
      <geometry>
        <mesh
          filename="file:///home/mickyas/ros2_ws/src/urdf_and_meshes_of_the_robot/meshes/Right_wheel.STL" />
      </geometry>
      <material
        name="Rubber ">
        <color
          rgba="0.29804 0.29804 0.29804 1" />
      </material>
    </visual>
    <collision>
      <origin
        xyz="0 0 0"
        rpy="0 0 0" />
      <geometry>
        <mesh
          filename="file:///home/mickyas/ros2_ws/src/urdf_and_meshes_of_the_robot/meshes/Right_wheel.STL" />
      </geometry>
    </collision>
  </link>
  <joint
    name="right_joint"
    type="continuous">
    <origin
      xyz="0 -0.22885 0.015"
      rpy="3.1416 0 0.41886" />
    <parent
      link="Lower_right_link" />
    <child
      link="Right_wheel" />
    <axis
      xyz="0 0 1" />
  </joint>


  <link
    name="lidar_link">
    <inertial>
      <origin
        xyz="-0.00748253542434936 0.0106650182159227 9.18484888063789E-05"
        rpy="0 0 0" />
      <mass
        value="0.023982866275303" />
      <inertia
        ixx="2.99648036688873E-06"
        ixy="7.71082922354325E-07"
        ixz="3.90085076397272E-09"
        iyy="5.35270613804163E-06"
        iyz="1.5091352201716E-08"
        izz="4.68185693441384E-06" />
    </inertial>
    <visual>
      <origin
        xyz="0 0 0"
        rpy="0 0 0" />
      <geometry>
        <mesh
          filename="file:///home/mickyas/ros2_ws/src/urdf_and_meshes_of_the_robot/meshes/lidar_link.STL" />
      </geometry>
      <material
        name="">
        <color
          rgba="0.298039215686275 0.298039215686275 0.298039215686275 1" />
      </material>
    </visual>
    <collision>
      <origin
        xyz="0 0 0"
        rpy="0 0 0" />
      <geometry>
        <mesh
          filename="file:///home/mickyas/ros2_ws/src/urdf_and_meshes_of_the_robot/meshes/lidar_link.STL" />
      </geometry>
    </collision>
  </link>
  <joint
    name="lidar_joint"
    type="fixed">
    <origin
      xyz="0.0118364652961996 4.41245333220815E-05 0.0326712986882367"
      rpy="1.5707963267949 0 0" />
    <parent
      link="BODY_link" />
    <child
      link="lidar_link" />
    <axis
      xyz="0 0 0" />
  </joint>
  <link
    name="camera_link">
    <inertial>
      <origin
        xyz="-1.00991565614951E-09 0.000394686414877599 0.00613911034094791"
        rpy="0 0 0" />
      <mass
        value="0.00182332100343475" />
      <inertia
        ixx="4.92416087597433E-08"
        ixy="1.34622570853428E-15"
        ixz="-2.02896607135891E-15"
        iyy="4.93405437288816E-08"
        iyz="3.4862884852944E-09"
        izz="4.40227961832514E-08" />
    </inertial>
    <visual>
      <origin
        xyz="0 0 0"
        rpy="0 0 0" />
      <geometry>
        <mesh
          filename="file:///home/mickyas/ros2_ws/src/urdf_and_meshes_of_the_robot/meshes/camera_link.STL" />
      </geometry>
      <material
        name="">
        <color
          rgba="0.298039215686275 0.298039215686275 0.298039215686275 1" />
      </material>
    </visual>
    <collision>
      <origin
        xyz="0 0 0"
        rpy="0 0 0" />
      <geometry>
        <mesh
          filename="file:///home/mickyas/ros2_ws/src/urdf_and_meshes_of_the_robot/meshes/camera_link.STL" />
      </geometry>
    </collision>
  </link>
  <joint
    name="camera_joint"
    type="fixed">
    <origin
      xyz="0 -0.0868463319293926 0.00105377166734255"
      rpy="1.74532925199432 0 0" />
    <parent
      link="BODY_link" />
    <child
      link="camera_link" />
    <axis
      xyz="0 0 0" />
  </joint>
  <link
    name="IMU_link">
    <inertial>
      <origin
        xyz="3.83749968898417E-06 0.00114501984172181 -0.000169625278521169"
        rpy="0 0 0" />
      <mass
        value="0.00107255708196703" />
      <inertia
        ixx="3.33321450865841E-08"
        ixy="-7.41397232762258E-12"
        ixz="3.16411212611588E-10"
        iyy="8.73841360657296E-08"
        iyz="3.39318638686155E-10"
        izz="5.53349807702084E-08" />
    </inertial>
    <visual>
      <origin
        xyz="0 0 0"
        rpy="0 0 0" />
      <geometry>
        <mesh
          filename="file:///home/mickyas/ros2_ws/src/urdf_and_meshes_of_the_robot/meshes/IMU_link.STL" />
      </geometry>
      <material
        name="">
        <color
          rgba="0.298039215686275 0.298039215686275 0.298039215686275 1" />
      </material>
    </visual>
    <collision>
      <origin
        xyz="0 0 0"
        rpy="0 0 0" />
      <geometry>
        <mesh
          filename="file:///home/mickyas/ros2_ws/src/urdf_and_meshes_of_the_robot/meshes/IMU_link.STL" />
      </geometry>
    </collision>
  </link>
  <joint
    name="IMU_joint"
    type="fixed">
    <origin
      xyz="0 0 0.025"
      rpy="1.5708 0 0" />
    <parent
      link="BODY_link" />
    <child
      link="IMU_link" />
    <axis
      xyz="0 0 0" />
  </joint>


      <!-- Gazebo sensor plugins -->
    <gazebo>
      <plugin name="gazebo_ros_factory" filename="libgazebo_ros_factory.so"/>
    </gazebo>

    <!-- IMU sensor plugin -->
    <gazebo reference="IMU_link">
      <plugin name="imu_plugin" filename="libgazebo_ros_imu_sensor.so">
          <sensor name="imu_sensor" type="imu">
              <always_on>1</always_on>
              <update_rate>100.0</update_rate>
              <visualize>true</visualize>
              <imu>
                  <noise>
                      <angular_velocity>0.01</angular_velocity>
                      <linear_acceleration>0.02</linear_acceleration>
                  </noise>
                  <topic>/imu</topic>
              </imu>
          </sensor>
      </plugin>
    </gazebo> 

    <!-- Camera plugin -->
    <gazebo reference="camera_link">
      <sensor name="camera_sensor" type="camera">
        <always_on>true</always_on>
        <update_rate>30.0</update_rate>
        <visualize>true</visualize>
        <noise>
          <type>gaussian</type>
          <mean>0.0</mean>
          <stddev>0.007</stddev>
        </noise>
        <camera>
          <horizontal_fov>1.3962634</horizontal_fov>
          <image>
            <width>640</width>
            <height>480</height>
            <format>R8G8B8</format>
          </image>
          <clip>
            <near>0.1</near>
            <far>100</far>
          </clip>
        </camera>
        <plugin name="camera_controller" filename="libgazebo_ros_camera.so">
          <cameraName>camera</cameraName>
          <imageTopicName>image_raw</imageTopicName>
          <cameraInfoTopicName>camera_info</cameraInfoTopicName>
          <frameName>camera_link</frameName>
        </plugin>
      </sensor>
    </gazebo>

    <!-- Lidar plugin -->
    <gazebo reference="lidar_link">
      <sensor type="ray" name="laser">
        <pose>0 0 0 0 0 0</pose>
        <ray>
          <scan>
            <horizontal>
              <samples>720</samples>
              <resolution>1</resolution>
              <min_angle>-1.5708</min_angle>
              <max_angle>1.5708</max_angle>
            </horizontal>
          </scan>
          <range>
            <min>0.1</min>
            <max>10.0</max>
            <resolution>0.01</resolution>
          </range>
        </ray>
        <plugin name="gazebo_ros_laser_controller" filename="libgazebo_ros_ray_sensor.so">
          <frame_name>lidar_link</frame_name>
          <topic_name>/scan</topic_name>
          <output_type>sensor_msgs/LaserScan</output_type>
        </plugin>
      </sensor>
    </gazebo>

    <!-- Joint state plugin for encoders (wheel rotation) -->
    <gazebo>
      <plugin name="joint_state_publisher" filename="libgazebo_ros_joint_state_publisher.so">
        <joint_name>Upper_left_joint</joint_name>
        <joint_name>Lower_left_joint</joint_name>
        <joint_name>left_joint</joint_name>
        <joint_name>Upper_right_joint</joint_name>
        <joint_name>Lower_right_joint</joint_name>
        <joint_name>right_joint</joint_name>
        <update_rate>50.0</update_rate>

      </plugin>
    </gazebo>

    
      <!-- Differential drive plugin 
      
      <left_wheel_joint> and <right_wheel_joint>: These tags point to the existing revolute joints for the left and right wheels in your robot’s URDF.
      <wheel_separation>: The distance between the left and right wheels (in meters).
      <wheel_radius>: The radius of the wheels (in meters).
      <odometry_frame>: The reference frame used for odometry. It’s common to use the odom frame for this.
      <odom_topic>: The topic where the odometry information will be published (e.g., /odom).
      <cmd_vel_topic>: The topic where velocity commands (linear and angular) will be published to control the robot’s motion.
      To control the robot, you will send commands to the /cmd_vel topic, typically in the form of geometry_msgs/Twist messages, which contain linear and angular velocities.
      -->
    <gazebo>
      <plugin name="gazebo_ros_diff_drive" filename="libgazebo_ros_diff_drive.so">
        <!-- Left and right wheel joints -->
        <left_wheel_joint>left_joint</left_wheel_joint>
        <right_wheel_joint>right_joint</right_wheel_joint>

        <!-- Wheel radius and separation between wheels -->
        <wheel_separation>0.226</wheel_separation>
        <wheel_radius>0.08255</wheel_radius>
  
        <!-- Update rate for the plugin -->
        <update_rate>50.0</update_rate>

        <!-- Odometry frame name -->
        <odometry_frame>odom</odometry_frame>
        <!-- Optional: set the robot's base frame -->
        <base_frame>base_link</base_frame>

        <!-- Provide the wheel velocities and odometry data -->
        <publish_rate>30.0</publish_rate>

        <!-- Odometry topic -->
        <odom_topic>/odom</odom_topic>
        <!-- Optional: set the topic for controlling the robot -->
        <cmd_vel_topic>/cmd_vel</cmd_vel_topic>
      </plugin>
    </gazebo>
</robot>