<!-- <?xml version="1.0" encoding="utf-8"?> -->
<!-- This URDF was automatically created by SolidWorks to URDF Exporter! Originally created by Stephen Brawner (brawner@gmail.com) 
     Commit Version: 1.6.0-4-g7f85cfe  Build Version: 1.6.7995.38578
     For more information, please see http://wiki.ros.org/sw_urdf_exporter -->
<robot
  name="urdf_and_meshes_of_the_robot">
  <link name="base_link"/>  <!-- Dummy link added -->

  <joint name="base_joint" type="fixed">
    <parent link="base_link"/>
    <child link="BODY_link"/>
  </joint>
  <link
    name="BODY_link">
    <inertial>
      <origin
        xyz="7.3062E-18 0.0022646 -0.021333"
        rpy="0 0 0" />
      <mass
        value="1.257" />
      <inertia
        ixx="0.0045914"
        ixy="1.4409E-18"
        ixz="-1.9104E-19"
        iyy="0.004286"
        iyz="0.00013476"
        izz="0.0063727" />
    </inertial>
    <visual>
      <origin
        xyz="0 0 0"
        rpy="0 0 0" />
      <geometry>
        <mesh
          filename="file:///home/mickyas/ros2_ws/src/urdf_and_meshes_of_the_robot/meshes/BODY_link.STL"/>
      </geometry>
      <material
        name="Alumuniam 1060 Alloy">
        <color
          rgba="0.89804 0.91765 0.92941 1" />
      </material>
    </visual>
    <collision>
      <origin
        xyz="0 0 0"
        rpy="0 0 0" />
      <geometry>
        <mesh
          filename="file:///home/mickyas/ros2_ws/src/urdf_and_meshes_of_the_robot/meshes/BODY_link.STL" />
      </geometry>
    </collision>
  </link>
  <link
    name="Upper_left_leg">
    <inertial>
      <origin
        xyz="6.6396E-09 -0.10715 0.021958"
        rpy="0 0 0" />
      <mass
        value="0.32627" />
      <inertia
        ixx="0.0021991"
        ixy="-1.3036E-10"
        ixz="-2.948E-10"
        iyy="4.2897E-05"
        iyz="3.6799E-06"
        izz="0.0022214" />
    </inertial>
    <visual>
      <origin
        xyz="0 0 0"
        rpy="0 0 0" />
      <geometry>
        <mesh
          filename="file:///home/mickyas/ros2_ws/src/urdf_and_meshes_of_the_robot/meshes/Upper_left_leg.STL" />
      </geometry>
      <material
        name="Alumuniam 1060 Alloy">
        <color
          rgba="0.29804 0.29804 0.29804 1" />
      </material>
    </visual>
    <collision>
      <origin
        xyz="0 0 0"
        rpy="0 0 0" />
      <geometry>
        <mesh
          filename="file:///home/mickyas/ros2_ws/src/urdf_and_meshes_of_the_robot/meshes/Upper_left_leg.STL" />
      </geometry>
    </collision>
  </link>
  <joint
    name="Upper_left_joint"
    type="revolute">
    <origin
      xyz="0.065 -0.0025 -0.055"
      rpy="1.5708 -0.5686 1.5708" />
    <parent
      link="BODY_link" />
    <child
      link="Upper_left_leg" />
    <axis
      xyz="0 0 -1" />
    <limit
      lower="0"
      upper="0"
      effort="0"
      velocity="0" />
  </joint>
  <link
    name="Lower_left_leg">
    <inertial>
      <origin
        xyz="3.3987E-08 -0.095731 0.0075383"
        rpy="0 0 0" />
      <mass
        value="0.20779" />
      <inertia
        ixx="0.0010103"
        ixy="7.9033E-11"
        ixz="1.1732E-10"
        iyy="1.2421E-05"
        iyz="7.5525E-07"
        izz="0.0010151" />
    </inertial>
    <visual>
      <origin
        xyz="0 0 0"
        rpy="0 0 0" />
      <geometry>
        <mesh
          filename="file:///home/mickyas/ros2_ws/src/urdf_and_meshes_of_the_robot/meshes/Lower_left_leg.STL" />
      </geometry>
      <material
        name="Alumuniam 1060 Alloy">
        <color
          rgba="0.29804 0.29804 0.29804 1" />
      </material>
    </visual>
    <collision>
      <origin
        xyz="0 0 0"
        rpy="0 0 0" />
      <geometry>
        <mesh
          filename="file:///home/mickyas/ros2_ws/src/urdf_and_meshes_of_the_robot/meshes/Lower_left_leg.STL" />
      </geometry>
    </collision>
  </link>
  <joint
    name="Lower_left_joint"
    type="revolute">
    <origin
      xyz="0 -0.24941 0.032"
      rpy="0 0 -1.2888" />
    <parent
      link="Upper_left_leg" />
    <child
      link="Lower_left_leg" />
    <axis
      xyz="0 0 1" />
    <limit
      lower="0"
      upper="0"
      effort="0"
      velocity="0" />
  </joint>
  <link
    name="Left_wheel">
    <inertial>
      <origin
        xyz="7.526E-08 -9.4982E-08 -0.021914"
        rpy="0 0 0" />
      <mass
        value="0.12382" />
      <inertia
        ixx="0.00019918"
        ixy="-2.4608E-10"
        ixz="-2.7634E-11"
        iyy="0.00019918"
        iyz="4.4186E-11"
        izz="0.0003757" />
    </inertial>
    <visual>
      <origin
        xyz="0 0 0"
        rpy="0 0 0" />
      <geometry>
        <mesh
          filename="file:///home/mickyas/ros2_ws/src/urdf_and_meshes_of_the_robot/meshes/Left_wheel.STL" />
      </geometry>
      <material
        name="Rubber">
        <color
          rgba="0.29804 0.29804 0.29804 1" />
      </material>
    </visual>
    <collision>
      <origin
        xyz="0 0 0"
        rpy="0 0 0" />
      <geometry>
        <mesh
          filename="file:///home/mickyas/ros2_ws/src/urdf_and_meshes_of_the_robot/meshes/Left_wheel.STL" />
      </geometry>
    </collision>
  </link>
  <joint
    name="Left_joint"
    type="continuous">
    <origin
      xyz="0 -0.22885 0.015"
      rpy="3.1416 0 0.81783" />
    <parent
      link="Lower_left_leg" />
    <child
      link="Left_wheel" />
    <axis
      xyz="0 0 1" />
    <limit
      lower="0"
      upper="0"
      effort="0"
      velocity="0" />
  </joint>
  <link
    name="Upper_right_link">
    <inertial>
      <origin
        xyz="9.6623E-09 -0.10715 0.021958"
        rpy="0 0 0" />
      <mass
        value="0.32627" />
      <inertia
        ixx="0.0021991"
        ixy="-1.7623E-10"
        ixz="-2.9281E-10"
        iyy="4.2897E-05"
        iyz="3.6798E-06"
        izz="0.0022214" />
    </inertial>
    <visual>
      <origin
        xyz="0 0 0"
        rpy="0 0 0" />
      <geometry>
        <mesh
          filename="file:///home/mickyas/ros2_ws/src/urdf_and_meshes_of_the_robot/meshes/Upper_right_link.STL" />
      </geometry>
      <material
        name="Alumuniam 1060 Alloy">
        <color
          rgba="0.29804 0.29804 0.29804 1" />
      </material>
    </visual>
    <collision>
      <origin
        xyz="0 0 0"
        rpy="0 0 0" />
      <geometry>
        <mesh
          filename="file:///home/mickyas/ros2_ws/src/urdf_and_meshes_of_the_robot/meshes/Upper_right_link.STL" />
      </geometry>
    </collision>
  </link>
  <joint
    name="Upper_right_joint"
    type="revolute">
    <origin
      xyz="-0.065 -0.0025 -0.055"
      rpy="1.5708 0.59611 -1.5708" />
    <parent
      link="BODY_link" />
    <child
      link="Upper_right_link" />
    <axis
      xyz="0 0 1" />
    <limit
      lower="0"
      upper="0"
      effort="0"
      velocity="0" />
  </joint>
  <link
    name="Lower_right_link">
    <inertial>
      <origin
        xyz="3.29E-08 -0.095731 0.0075383"
        rpy="0 0 0" />
      <mass
        value="0.20779" />
      <inertia
        ixx="0.0010103"
        ixy="8.8706E-11"
        ixz="1.1747E-10"
        iyy="1.2421E-05"
        iyz="7.5523E-07"
        izz="0.0010151" />
    </inertial>
    <visual>
      <origin
        xyz="0 0 0"
        rpy="0 0 0" />
      <geometry>
        <mesh
          filename="file:///home/mickyas/ros2_ws/src/urdf_and_meshes_of_the_robot/meshes/Lower_right_link.STL" />
      </geometry>
      <material
        name="Alumuniam 1060 Alloy">
        <color
          rgba="0.29804 0.29804 0.29804 1" />
      </material>
    </visual>
    <collision>
      <origin
        xyz="0 0 0"
        rpy="0 0 0" />
      <geometry>
        <mesh
          filename="file:///home/mickyas/ros2_ws/src/urdf_and_meshes_of_the_robot/meshes/Lower_right_link.STL" />
      </geometry>
    </collision>
  </link>
  <joint
    name="Lower_right_joint"
    type="revolute">
    <origin
      xyz="0 -0.24941 0.034"
      rpy="0 0 1.3094" />
    <parent
      link="Upper_right_link" />
    <child
      link="Lower_right_link" />
    <axis
      xyz="0 0 1" />
    <limit
      lower="0"
      upper="0"
      effort="0"
      velocity="0" />
  </joint>
  <link
    name="Right_wheel">
    <inertial>
      <origin
        xyz="2.9114E-08 -9.5306E-09 -0.021914"
        rpy="0 0 0" />
      <mass
        value="0.12382" />
      <inertia
        ixx="0.00019918"
        ixy="-2.1966E-10"
        ixz="-1.9165E-11"
        iyy="0.00019918"
        iyz="2.7688E-11"
        izz="0.0003757" />
    </inertial>
    <visual>
      <origin
        xyz="0 0 0"
        rpy="0 0 0" />
      <geometry>
        <mesh
          filename="file:///home/mickyas/ros2_ws/src/urdf_and_meshes_of_the_robot/meshes/Right_wheel.STL" />
      </geometry>
      <material
        name="Rubber ">
        <color
          rgba="0.29804 0.29804 0.29804 1" />
      </material>
    </visual>
    <collision>
      <origin
        xyz="0 0 0"
        rpy="0 0 0" />
      <geometry>
        <mesh
          filename="file:///home/mickyas/ros2_ws/src/urdf_and_meshes_of_the_robot/meshes/Right_wheel.STL" />
      </geometry>
    </collision>
  </link>
  <joint
    name="Right_joint"
    type="continuous">
    <origin
      xyz="0 -0.22885 0.015"
      rpy="3.1416 0 0.41886" />
    <parent
      link="Lower_right_link" />
    <child
      link="Right_wheel" />
    <axis
      xyz="0 0 1" />
  </joint>
</robot>